Workbook

Sheet 1. Параметры
A1: Omnia.AI · Токен-экономика — параметры (v1)
A2: Все жёлтые ячейки — input. Меняй и пересчитай. Чёрные — формулы.
A4: Параметр | B4: Значение | C4: Комментарий
A5: Курс ₽/$ | B5: 100 | C5: Базовый курс на 2025
A6: Markup на токены | B6: 2.8 | C6: Себестоимость + ~64% маржа на токенах
A7: Output share | B7: 0.5 | C7: Доля output в общем объёме токенов
A8: Размер сообщения, токенов | B8: 8000 | C8: 5 000 input + 3 000 output (consrv. среднее)

Sheet 2. Модели LLM
A1: 8 моделей · себестоимость и retail-цена
A2: Себест ₽/1М = (цена input × 0.5 + цена output × 0.5) × курс ₽/$. Цена клиенту = себест × наценка 2.8.
A4: Модель | B4: Категория | C4: Input $/1M | D4: Output $/1M | E4: Себест. ₽/1M | F4: Цена клиенту ₽/1M
A5: DeepSeek V3.2 | B5: ультра-эконом | C5: 0.28 | D5: 0.42 | E5: =(C5*(1-'1. Параметры'!$B$7)+D5*'1. Параметры'!$B$7)*'1. Параметры'!$B$5 | F5: =E5*'1. Параметры'!$B$6
A6: Qwen 3 235B (self-hosted) | B6: ультра-эконом | C6: 0.5 | D6: 0.5 | E6: =(C6*(1-'1. Параметры'!$B$7)+D6*'1. Параметры'!$B$7)*'1. Параметры'!$B$5 | F6: =E6*'1. Параметры'!$B$6
A7: Gemini 2.5 Flash | B7: эконом | C7: 0.3 | D7: 2.5 | E7: =(C7*(1-'1. Параметры'!$B$7)+D7*'1. Параметры'!$B$7)*'1. Параметры'!$B$5 | F7: =E7*'1. Параметры'!$B$6
A8: Claude Haiku 4.5 | B8: баланс | C8: 1 | D8: 5 | E8: =(C8*(1-'1. Параметры'!$B$7)+D8*'1. Параметры'!$B$7)*'1. Параметры'!$B$5 | F8: =E8*'1. Параметры'!$B$6
A9: GigaChat 2 Pro | B9: 152-ФЗ | C9: 5 | D9: 5 | E9: =(C9*(1-'1. Параметры'!$B$7)+D9*'1. Параметры'!$B$7)*'1. Параметры'!$B$5 | F9: =E9*'1. Параметры'!$B$6
A10: GPT-4.1 | B10: премиум | C10: 2 | D10: 8 | E10: =(C10*(1-'1. Параметры'!$B$7)+D10*'1. Параметры'!$B$7)*'1. Параметры'!$B$5 | F10: =E10*'1. Параметры'!$B$6
A11: Claude Sonnet 4.6 | B11: премиум | C11: 3 | D11: 15 | E11: =(C11*(1-'1. Параметры'!$B$7)+D11*'1. Параметры'!$B$7)*'1. Параметры'!$B$5 | F11: =E11*'1. Параметры'!$B$6
A12: YandexGPT 5 Pro | B12: 152-ФЗ премиум | C12: 8 | D12: 16 | E12: =(C12*(1-'1. Параметры'!$B$7)+D12*'1. Параметры'!$B$7)*'1. Параметры'!$B$5 | F12: =E12*'1. Параметры'!$B$6

Sheet 3. Цена сообщения
A1: Стоимость 1 сообщения · 8 000 токенов
A2: 1 сообщение = размер_сообщения / 1 000 000 миллионов токенов. Меняй msg_size в 1.Параметры.
A4: Модель | B4: Себест ₽/сообщ | C4: Цена клиенту ₽/сообщ | D4: Маржа ₽/сообщ | E4: Маржа %
A5: DeepSeek V3.2 | B5: ='2. Модели LLM'!E5*'1. Параметры'!$B$8/1000000 | C5: ='2. Модели LLM'!F5*'1. Параметры'!$B$8/1000000 | D5: =C5-B5 | E5: =(C5-B5)/C5
A6: Qwen 3 235B (self-hosted) | B6: ='2. Модели LLM'!E6*'1. Параметры'!$B$8/1000000 | C6: ='2. Модели LLM'!F6*'1. Параметры'!$B$8/1000000 | D6: =C6-B6 | E6: =(C6-B6)/C6
A7: Gemini 2.5 Flash | B7: ='2. Модели LLM'!E7*'1. Параметры'!$B$8/1000000 | C7: ='2. Модели LLM'!F7*'1. Параметры'!$B$8/1000000 | D7: =C7-B7 | E7: =(C7-B7)/C7
A8: Claude Haiku 4.5 | B8: ='2. Модели LLM'!E8*'1. Параметры'!$B$8/1000000 | C8: ='2. Модели LLM'!F8*'1. Параметры'!$B$8/1000000 | D8: =C8-B8 | E8: =(C8-B8)/C8
A9: GigaChat 2 Pro | B9: ='2. Модели LLM'!E9*'1. Параметры'!$B$8/1000000 | C9: ='2. Модели LLM'!F9*'1. Параметры'!$B$8/1000000 | D9: =C9-B9 | E9: =(C9-B9)/C9
A10: GPT-4.1 | B10: ='2. Модели LLM'!E10*'1. Параметры'!$B$8/1000000 | C10: ='2. Модели LLM'!F10*'1. Параметры'!$B$8/1000000 | D10: =C10-B10 | E10: =(C10-B10)/C10
A11: Claude Sonnet 4.6 | B11: ='2. Модели LLM'!E11*'1. Параметры'!$B$8/1000000 | C11: ='2. Модели LLM'!F11*'1. Параметры'!$B$8/1000000 | D11: =C11-B11 | E11: =(C11-B11)/C11
A12: YandexGPT 5 Pro | B12: ='2. Модели LLM'!E12*'1. Параметры'!$B$8/1000000 | C12: ='2. Модели LLM'!F12*'1. Параметры'!$B$8/1000000 | D12: =C12-B12 | E12: =(C12-B12)/C12

Sheet 4. Объёмы 50-200-1000
A1: Сколько стоит 50 / 200 / 1 000 сообщений
A2: Цена что заплатит клиент · меняй размер сообщения в 1. Параметры.
A4: Модель | B4: 50 сообщений | C4: 200 сообщений | D4: 1 000 сообщений | E4: Токенов всего
A5: DeepSeek V3.2 | B5: ='3. Цена сообщения'!C5*50 | C5: ='3. Цена сообщения'!C5*200 | D5: ='3. Цена сообщения'!C5*1000 | E5: =1000*'1. Параметры'!$B$8/1000000
A6: Qwen 3 235B (self-hosted) | B6: ='3. Цена сообщения'!C6*50 | C6: ='3. Цена сообщения'!C6*200 | D6: ='3. Цена сообщения'!C6*1000 | E6: =1000*'1. Параметры'!$B$8/1000000
A7: Gemini 2.5 Flash | B7: ='3. Цена сообщения'!C7*50 | C7: ='3. Цена сообщения'!C7*200 | D7: ='3. Цена сообщения'!C7*1000 | E7: =1000*'1. Параметры'!$B$8/1000000
A8: Claude Haiku 4.5 | B8: ='3. Цена сообщения'!C8*50 | C8: ='3. Цена сообщения'!C8*200 | D8: ='3. Цена сообщения'!C8*1000 | E8: =1000*'1. Параметры'!$B$8/1000000
A9: GigaChat 2 Pro | B9: ='3. Цена сообщения'!C9*50 | C9: ='3. Цена сообщения'!C9*200 | D9: ='3. Цена сообщения'!C9*1000 | E9: =1000*'1. Параметры'!$B$8/1000000
A10: GPT-4.1 | B10: ='3. Цена сообщения'!C10*50 | C10: ='3. Цена сообщения'!C10*200 | D10: ='3. Цена сообщения'!C10*1000 | E10: =1000*'1. Параметры'!$B$8/1000000
A11: Claude Sonnet 4.6 | B11: ='3. Цена сообщения'!C11*50 | C11: ='3. Цена сообщения'!C11*200 | D11: ='3. Цена сообщения'!C11*1000 | E11: =1000*'1. Параметры'!$B$8/1000000
A12: YandexGPT 5 Pro | B12: ='3. Цена сообщения'!C12*50 | C12: ='3. Цена сообщения'!C12*200 | D12: ='3. Цена сообщения'!C12*1000 | E12: =1000*'1. Параметры'!$B$8/1000000
A14: Токенов суммарно (для 1 000 msg) | B14: =50*'1. Параметры'!$B$8 | C14: =200*'1. Параметры'!$B$8 | D14: =1000*'1. Параметры'!$B$8 | E14: токенов

Sheet 5. Кошелёк → сообщения
A1: Сколько сообщений покрывает кошелёк каждого тарифа
A2: Если пользователь использует только одну модель.
A4: Тариф | B4: Кошелёк ₽ | C4: DeepSeek | D4: Qwen | E4: Gemini Flash | F4: Haiku 4.5 | G4: GigaChat | H4: GPT-4.1 | I4: Sonnet 4.6 | J4: YandexGPT
A5: Free (5 дней) | B5: 500 | C5: =ROUNDDOWN(B5/'3. Цена сообщения'!C5,0) | D5: =ROUNDDOWN(B5/'3. Цена сообщения'!C6,0) | E5: =ROUNDDOWN(B5/'3. Цена сообщения'!C7,0) | F5: =ROUNDDOWN(B5/'3. Цена сообщения'!C8,0) | G5: =ROUNDDOWN(B5/'3. Цена сообщения'!C9,0) | H5: =ROUNDDOWN(B5/'3. Цена сообщения'!C10,0) | I5: =ROUNDDOWN(B5/'3. Цена сообщения'!C11,0) | J5: =ROUNDDOWN(B5/'3. Цена сообщения'!C12,0)
A6: Lite | B6: 1000 | C6: =ROUNDDOWN(B6/'3. Цена сообщения'!C5,0) | D6: =ROUNDDOWN(B6/'3. Цена сообщения'!C6,0) | E6: =ROUNDDOWN(B6/'3. Цена сообщения'!C7,0) | F6: =ROUNDDOWN(B6/'3. Цена сообщения'!C8,0) | G6: =ROUNDDOWN(B6/'3. Цена сообщения'!C9,0) | H6: =ROUNDDOWN(B6/'3. Цена сообщения'!C10,0) | I6: =ROUNDDOWN(B6/'3. Цена сообщения'!C11,0) | J6: =ROUNDDOWN(B6/'3. Цена сообщения'!C12,0)
A7: Starter | B7: 2500 | C7: =ROUNDDOWN(B7/'3. Цена сообщения'!C5,0) | D7: =ROUNDDOWN(B7/'3. Цена сообщения'!C6,0) | E7: =ROUNDDOWN(B7/'3. Цена сообщения'!C7,0) | F7: =ROUNDDOWN(B7/'3. Цена сообщения'!C8,0) | G7: =ROUNDDOWN(B7/'3. Цена сообщения'!C9,0) | H7: =ROUNDDOWN(B7/'3. Цена сообщения'!C10,0) | I7: =ROUNDDOWN(B7/'3. Цена сообщения'!C11,0) | J7: =ROUNDDOWN(B7/'3. Цена сообщения'!C12,0)
A8: Pro | B8: 6000 | C8: =ROUNDDOWN(B8/'3. Цена сообщения'!C5,0) | D8: =ROUNDDOWN(B8/'3. Цена сообщения'!C6,0) | E8: =ROUNDDOWN(B8/'3. Цена сообщения'!C7,0) | F8: =ROUNDDOWN(B8/'3. Цена сообщения'!C8,0) | G8: =ROUNDDOWN(B8/'3. Цена сообщения'!C9,0) | H8: =ROUNDDOWN(B8/'3. Цена сообщения'!C10,0) | I8: =ROUNDDOWN(B8/'3. Цена сообщения'!C11,0) | J8: =ROUNDDOWN(B8/'3. Цена сообщения'!C12,0)
A9: Enterprise | B9: 18000 | C9: =ROUNDDOWN(B9/'3. Цена сообщения'!C5,0) | D9: =ROUNDDOWN(B9/'3. Цена сообщения'!C6,0) | E9: =ROUNDDOWN(B9/'3. Цена сообщения'!C7,0) | F9: =ROUNDDOWN(B9/'3. Цена сообщения'!C8,0) | G9: =ROUNDDOWN(B9/'3. Цена сообщения'!C9,0) | H9: =ROUNDDOWN(B9/'3. Цена сообщения'!C10,0) | I9: =ROUNDDOWN(B9/'3. Цена сообщения'!C11,0) | J9: =ROUNDDOWN(B9/'3. Цена сообщения'!C12,0)

Sheet 6. Mix-сценарии
A1: 4 типичных профиля пользователя
A2: Меняй веса в столбце B — пересчёт автоматический.
A4: Модель | B4: A. MVP-эконом | C4: B. Балансный | D4: C. Премиум | E4: D. 152-ФЗ
A5: DeepSeek V3.2 | B5: 0.7 | C5: 0.4 | D5: 0 | E5: 0
A6: Qwen 3 235B | B6: 0 | C6: 0 | D6: 0 | E6: 0
A7: Gemini 2.5 Flash | B7: 0 | C7: 0.2 | D7: 0 | E7: 0
A8: Claude Haiku 4.5 | B8: 0.2 | C8: 0.3 | D8: 0.3 | E8: 0
A9: GigaChat 2 Pro | B9: 0 | C9: 0 | D9: 0 | E9: 0.3
A10: GPT-4.1 | B10: 0 | C10: 0 | D10: 0.2 | E10: 0
A11: Claude Sonnet 4.6 | B11: 0.1 | C11: 0.1 | D11: 0.5 | E11: 0.1
A12: YandexGPT 5 Pro | B12: 0 | C12: 0 | D12: 0 | E12: 0.6
A13: Сумма (должна = 100%) | B13: =SUM(B5:B12) | C13: =SUM(C5:C12) | D13: =SUM(D5:D12) | E13: =SUM(E5:E12)
A15: Себест ₽/сообщ | B15: =SUMPRODUCT(B5:B12,'3. Цена сообщения'!B5:B12) | C15: =SUMPRODUCT(C5:C12,'3. Цена сообщения'!B5:B12) | D15: =SUMPRODUCT(D5:D12,'3. Цена сообщения'!B5:B12) | E15: =SUMPRODUCT(E5:E12,'3. Цена сообщения'!B5:B12)
A16: Цена клиенту ₽/сообщ | B16: =SUMPRODUCT(B5:B12,'3. Цена сообщения'!C5:C12) | C16: =SUMPRODUCT(C5:C12,'3. Цена сообщения'!C5:C12) | D16: =SUMPRODUCT(D5:D12,'3. Цена сообщения'!C5:C12) | E16: =SUMPRODUCT(E5:E12,'3. Цена сообщения'!C5:C12)
A18: 50 сообщений (₽) | B18: =B16*50 | C18: =C16*50 | D18: =D16*50 | E18: =E16*50
A19: 200 сообщений (₽) | B19: =B16*200 | C19: =C16*200 | D19: =D16*200 | E19: =E16*200
A20: 1 000 сообщений (₽) | B20: =B16*1000 | C20: =C16*1000 | D20: =D16*1000 | E20: =E16*1000
A22: Сообщений на 1 000 ₽ кошелёк (Lite) | B22: =ROUNDDOWN(1000/B16,0) | C22: =ROUNDDOWN(1000/C16,0) | D22: =ROUNDDOWN(1000/D16,0) | E22: =ROUNDDOWN(1000/E16,0)
A23: Сообщений на 2 500 ₽ (Starter) | B23: =ROUNDDOWN(2500/B16,0) | C23: =ROUNDDOWN(2500/C16,0) | D23: =ROUNDDOWN(2500/D16,0) | E23: =ROUNDDOWN(2500/E16,0)
A24: Сообщений на 6 000 ₽ (Pro) | B24: =ROUNDDOWN(6000/B16,0) | C24: =ROUNDDOWN(6000/C16,0) | D24: =ROUNDDOWN(6000/D16,0) | E24: =ROUNDDOWN(6000/E16,0)
A25: Сообщений на 18 000 ₽ (Enterprise) | B25: =ROUNDDOWN(18000/B16,0) | C25: =ROUNDDOWN(18000/C16,0) | D25: =ROUNDDOWN(18000/D16,0) | E25: =ROUNDDOWN(18000/E16,0)

Sheet 7. Маржа по тарифам
A1: Маржа платформы при условии что user сжигает весь кошелёк
A2: Профиль B (балансный) — типичный SMB. Меняй цены/кошельки в синих ячейках.
A4: Тариф | B4: Цена ₽/мес | C4: Кошелёк ₽ | D4: LLM-COGS ₽ | E4: Сервер COGS ₽ | F4: Платёжная комиссия (3%) | G4: Прочее (+10%) | H4: Маржа ₽/мес | I4: Маржа %
A5: Free | B5: 0 | C5: 500 | D5: =C5*'6. Mix-сценарии'!C15/'6. Mix-сценарии'!C16 | E5: 0 | F5: =B5*0.03 | G5: =B5*0.10 | H5: =B5-D5-E5-F5-G5 | I5: =IF(B5=0,0,H5/B5)
A6: Lite | B6: 990 | C6: 1000 | D6: =C6*'6. Mix-сценарии'!C15/'6. Mix-сценарии'!C16 | E6: 0 | F6: =B6*0.03 | G6: =B6*0.10 | H6: =B6-D6-E6-F6-G6 | I6: =IF(B6=0,0,H6/B6)
A7: Starter | B7: 2990 | C7: 2500 | D7: =C7*'6. Mix-сценарии'!C15/'6. Mix-сценарии'!C16 | E7: 600 | F7: =B7*0.03 | G7: =B7*0.10 | H7: =B7-D7-E7-F7-G7 | I7: =IF(B7=0,0,H7/B7)
A8: Pro | B8: 7990 | C8: 6000 | D8: =C8*'6. Mix-сценарии'!C15/'6. Mix-сценарии'!C16 | E8: 3000 | F8: =B8*0.03 | G8: =B8*0.10 | H8: =B8-D8-E8-F8-G8 | I8: =IF(B8=0,0,H8/B8)
A9: Enterprise | B9: 19990 | C9: 18000 | D9: =C9*'6. Mix-сценарии'!C15/'6. Mix-сценарии'!C16 | E9: 8000 | F9: =B9*0.03 | G9: =B9*0.10 | H9: =B9-D9-E9-F9-G9 | I9: =IF(B9=0,0,H9/B9)
A12: Free отрицателен = это lead-magnet. Окупается через 12% conversion в Lite.
A13: LLM-COGS считается через Mix-профиль B. Если user полностью на DeepSeek — маржа выше; если на Sonnet — может уйти в минус.

Sheet 8. Размер сообщения
A1: Чувствительность к размеру сообщения
A2: Если средний msg = 4K (мелкие правки) / 8K (стандарт) / 16K (большие фичи) / 30K (полная страница)
A4: Модель (на 6 000 ₽ кошелёк = Pro) | B4: 4 000 ток. | C4: 8 000 ток. | D4: 16 000 ток. | E4: 30 000 ток.
A5: DeepSeek V3.2 | B5: =ROUNDDOWN(6000*1000000/('2. Модели LLM'!F5*4000),0) | C5: =ROUNDDOWN(6000*1000000/('2. Модели LLM'!F5*8000),0) | D5: =ROUNDDOWN(6000*1000000/('2. Модели LLM'!F5*16000),0) | E5: =ROUNDDOWN(6000*1000000/('2. Модели LLM'!F5*30000),0)
A6: Qwen 3 235B (self-hosted) | B6: =ROUNDDOWN(6000*1000000/('2. Модели LLM'!F6*4000),0) | C6: =ROUNDDOWN(6000*1000000/('2. Модели LLM'!F6*8000),0) | D6: =ROUNDDOWN(6000*1000000/('2. Модели LLM'!F6*16000),0) | E6: =ROUNDDOWN(6000*1000000/('2. Модели LLM'!F6*30000),0)
A7: Gemini 2.5 Flash | B7: =ROUNDDOWN(6000*1000000/('2. Модели LLM'!F7*4000),0) | C7: =ROUNDDOWN(6000*1000000/('2. Модели LLM'!F7*8000),0) | D7: =ROUNDDOWN(6000*1000000/('2. Модели LLM'!F7*16000),0) | E7: =ROUNDDOWN(6000*1000000/('2. Модели LLM'!F7*30000),0)
A8: Claude Haiku 4.5 | B8: =ROUNDDOWN(6000*1000000/('2. Модели LLM'!F8*4000),0) | C8: =ROUNDDOWN(6000*1000000/('2. Модели LLM'!F8*8000),0) | D8: =ROUNDDOWN(6000*1000000/('2. Модели LLM'!F8*16000),0) | E8: =ROUNDDOWN(6000*1000000/('2. Модели LLM'!F8*30000),0)
A9: GigaChat 2 Pro | B9: =ROUNDDOWN(6000*1000000/('2. Модели LLM'!F9*4000),0) | C9: =ROUNDDOWN(6000*1000000/('2. Модели LLM'!F9*8000),0) | D9: =ROUNDDOWN(6000*1000000/('2. Модели LLM'!F9*16000),0) | E9: =ROUNDDOWN(6000*1000000/('2. Модели LLM'!F9*30000),0)
A10: GPT-4.1 | B10: =ROUNDDOWN(6000*1000000/('2. Модели LLM'!F10*4000),0) | C10: =ROUNDDOWN(6000*1000000/('2. Модели LLM'!F10*8000),0) | D10: =ROUNDDOWN(6000*1000000/('2. Модели LLM'!F10*16000),0) | E10: =ROUNDDOWN(6000*1000000/('2. Модели LLM'!F10*30000),0)
A11: Claude Sonnet 4.6 | B11: =ROUNDDOWN(6000*1000000/('2. Модели LLM'!F11*4000),0) | C11: =ROUNDDOWN(6000*1000000/('2. Модели LLM'!F11*8000),0) | D11: =ROUNDDOWN(6000*1000000/('2. Модели LLM'!F11*16000),0) | E11: =ROUNDDOWN(6000*1000000/('2. Модели LLM'!F11*30000),0)
A12: YandexGPT 5 Pro | B12: =ROUNDDOWN(6000*1000000/('2. Модели LLM'!F12*4000),0) | C12: =ROUNDDOWN(6000*1000000/('2. Модели LLM'!F12*8000),0) | D12: =ROUNDDOWN(6000*1000000/('2. Модели LLM'!F12*16000),0) | E12: =ROUNDDOWN(6000*1000000/('2. Модели LLM'!F12*30000),0)
A14: Размер сообщения зависит от сложности задачи.
A15: • 4K — «измени цвет», «передвинь блок» (мелкие правки)
A16: • 8K — стандарт: добавить секцию, изменить логику формы
A17: • 16K — фича целиком: новая страница с интеграцией
A18: • 30K — полная переделка: миграция БД + рефактор

Sheet 9. Топ-up пакеты
A1: Дополнительные пакеты токенов поверх подписки
A2: Скидка на крупные пакеты — стимул retention и upsell.
A4: Пакет (номинал) | B4: Цена клиенту | C4: Скидка | D4: DeepSeek msg | E4: Haiku msg | F4: Sonnet msg | G4: YandexGPT msg
A5: 500 ₽ | B5: 500 | C5: 0 | D5: =ROUNDDOWN(500/'3. Цена сообщения'!C5,0) | E5: =ROUNDDOWN(500/'3. Цена сообщения'!C8,0) | F5: =ROUNDDOWN(500/'3. Цена сообщения'!C11,0) | G5: =ROUNDDOWN(500/'3. Цена сообщения'!C12,0)
A6: 2 000 ₽ | B6: 1800 | C6: 0.1 | D6: =ROUNDDOWN(2000/'3. Цена сообщения'!C5,0) | E6: =ROUNDDOWN(2000/'3. Цена сообщения'!C8,0) | F6: =ROUNDDOWN(2000/'3. Цена сообщения'!C11,0) | G6: =ROUNDDOWN(2000/'3. Цена сообщения'!C12,0)
A7: 5 000 ₽ | B7: 4250 | C7: 0.15 | D7: =ROUNDDOWN(5000/'3. Цена сообщения'!C5,0) | E7: =ROUNDDOWN(5000/'3. Цена сообщения'!C8,0) | F7: =ROUNDDOWN(5000/'3. Цена сообщения'!C11,0) | G7: =ROUNDDOWN(5000/'3. Цена сообщения'!C12,0)
A8: 10 000 ₽ | B8: 8000 | C8: 0.2 | D8: =ROUNDDOWN(10000/'3. Цена сообщения'!C5,0) | E8: =ROUNDDOWN(10000/'3. Цена сообщения'!C8,0) | F8: =ROUNDDOWN(10000/'3. Цена сообщения'!C11,0) | G8: =ROUNDDOWN(10000/'3. Цена сообщения'!C12,0)
A9: 25 000 ₽ | B9: 18750 | C9: 0.25 | D9: =ROUNDDOWN(25000/'3. Цена сообщения'!C5,0) | E9: =ROUNDDOWN(25000/'3. Цена сообщения'!C8,0) | F9: =ROUNDDOWN(25000/'3. Цена сообщения'!C11,0) | G9: =ROUNDDOWN(25000/'3. Цена сообщения'!C12,0)

Sheet 10. Сообщения на проект
A1: Типичная нагрузка на 1 проект — сколько сообщений в месяц
A2: Зависит от типа проекта и стадии жизненного цикла. Цифры — оценка по бенчмаркам Lovable/Cursor/v0.
A4: Тип проекта | B4: Стадия | C4: Сообщений/мес (диапазон) | D4: Среднее | E4: На каком тарифе сидит юзер
A5: Лендинг (1 страница) | B5: Сборка с нуля | C5: 30–60 | D5: 45 | E5: Lite (266 msg на бал.) ✓
A6: Лендинг | B6: Активные правки (1-2 нед) | C6: 20–40 | D6: 30 | E6: Lite ✓
A7: Лендинг | B7: Поддержка / месяц | C7: 5–15 | D7: 10 | E7: Lite ✓
A8: Магазин e-commerce | B8: Сборка с нуля | C8: 80–150 | D8: 120 | E8: Starter (502) ✓
A9: Магазин | B9: Добавление товаров / правки | C9: 30–60 | D9: 45 | E9: Lite ✓
A10: Магазин | B10: Сезон / маркетинг (распродажа) | C10: 60–120 | D10: 90 | E10: Starter ✓
A11: Корп-сайт SMB | B11: Сборка с нуля | C11: 60–120 | D11: 90 | E11: Starter ✓
A12: Корп-сайт | B12: Поддержка | C12: 15–30 | D12: 22 | E12: Lite ✓
A13: Портфолио / визитка | B13: Сборка с нуля | C13: 20–50 | D13: 35 | E13: Lite ✓
A14: Портфолио | B14: Обновление работ | C14: 5–15 | D14: 10 | E14: Lite ✓
A15: SaaS-MVP с backend | B15: Сборка с нуля | C15: 200–400 | D15: 300 | E15: Pro (1 205) ✓
A16: SaaS-MVP | B16: Активный рост / новые фичи | C16: 100–250 | D16: 175 | E16: Pro ✓
... A22: Агентство · 5 клиентов параллельно | B22: Активная разработка | C22: 500–1000 | D22: 750 | E22: Enterprise (3 614) ✓
A25: ВЫВОДЫ
A26: • 80% SMB-проектов укладываются в Lite (1 000 ₽ кошелёк = 200 msg на бал. mix).
A27: • Сборка магазина / SaaS требует Starter или Pro в первый месяц, потом downgrade.
A28: • Pro оправдан только при 200+ msg/мес — это активная разработка SaaS-MVP, чат-боты, или 2-3 проекта одновременно.
A29: • Enterprise — для агентств с 5+ клиентами одновременно или больших проектов 1 000+ msg.
A30: • Реальный паттерн: первый месяц активной сборки — выше тариф, потом downgrade на поддержку. Учитываем в churn-ставке.

Sheet 11. Кеширование промптов
A1: Что даёт кеширование промптов (когда 70% input — cache hit)
A2: Anthropic / OpenAI / Google: cached input reads = 10% от raw input. На повторных запросах в сессии это +10-20% margin.
A4: Параметр | B4: Значение
A5: Cache hit rate | B5: 0.7 | C5: Доля input-токенов из cache (типично для повторных запросов в сессии)
A6: Cache read price (доля от raw input) | B6: 0.1 | C6: Anthropic/OpenAI стандарт: −90% на cached reads
A8: Эффективный множитель input | B8: =1-B5*(1-B6) | C8: 0.37 при 70% hit / 10% read price → −63% на input
A11: Модель | B11: Без кеша · себест/сообщ | C11: С кешем · себест/сообщ | D11: Экономия % | E11: Без · цена клиенту/сообщ | F11: С · цена клиенту/сообщ | G11: Экономия для нас ₽/msg
A12: DeepSeek V3.2 | B12: ='3. Цена сообщения'!B5 | C12: =(0.28*(1-'1. Параметры'!$B$7)*$B$8+0.42*'1. Параметры'!$B$7)*'1. Параметры'!$B$5*'1. Параметры'!$B$8/1000000 | D12: =(B12-C12)/B12 | E12: ='3. Цена сообщения'!C5 | F12: =C12*'1. Параметры'!$B$6 | G12: =B12-C12
A13: Qwen 3 235B (self-hosted) | B13: ='3. Цена сообщения'!B6 | C13: =(0.5*(1-'1. Параметры'!$B$7)*$B$8+0.5*'1. Параметры'!$B$7)*'1. Параметры'!$B$5*'1. Параметры'!$B$8/1000000 | D13: =(B13-C13)/B13 | E13: ='3. Цена сообщения'!C6 | F13: =C13*'1. Параметры'!$B$6 | G13: =B13-C13
A14: Gemini 2.5 Flash | B14: ='3. Цена сообщения'!B7 | C14: =(0.3*(1-'1. Параметры'!$B$7)*$B$8+2.5*'1. Параметры'!$B$7)*'1. Параметры'!$B$5*'1. Параметры'!$B$8/1000000 | D14: =(B14-C14)/B14 | E14: ='3. Цена сообщения'!C7 | F14: =C14*'1. Параметры'!$B$6 | G14: =B14-C14
A15: Claude Haiku 4.5 | B15: ='3. Цена сообщения'!B8 | C15: =(1.0*(1-'1. Параметры'!$B$7)*$B$8+5.0*'1. Параметры'!$B$7)*'1. Параметры'!$B$5*'1. Параметры'!$B$8/1000000 | D15: =(B15-C15)/B15 | E15: ='3. Цена сообщения'!C8 | F15: =C15*'1. Параметры'!$B$6 | G15: =B15-C15
A16: GigaChat 2 Pro | B16: ='3. Цена сообщения'!B9 | C16: =(5.0*(1-'1. Параметры'!$B$7)*$B$8+5.0*'1. Параметры'!$B$7)*'1. Параметры'!$B$5*'1. Параметры'!$B$8/1000000 | D16: =(B16-C16)/B16 | E16: ='3. Цена сообщения'!C9 | F16: =C16*'1. Параметры'!$B$6 | G16: =B16-C16
A17: GPT-4.1 | B17: ='3. Цена сообщения'!B10 | C17: =(2.0*(1-'1. Параметры'!$B$7)*$B$8+8.0*'1. Параметры'!$B$7)*'1. Параметры'!$B$5*'1. Параметры'!$B$8/1000000 | D17: =(B17-C17)/B17 | E17: ='3. Цена сообщения'!C10 | F17: =C17*'1. Параметры'!$B$6 | G17: =B17-C17
A18: Claude Sonnet 4.6 | B18: ='3. Цена сообщения'!B11 | C18: =(3.0*(1-'1. Параметры'!$B$7)*$B$8+15.0*'1. Параметры'!$B$7)*'1. Параметры'!$B$5*'1. Параметры'!$B$8/1000000 | D18: =(B18-C18)/B18 | E18: ='3. Цена сообщения'!C11 | F18: =C18*'1. Параметры'!$B$6 | G18: =B18-C18
A19: YandexGPT 5 Pro | B19: ='3. Цена сообщения'!B12 | C19: =(8.0*(1-'1. Параметры'!$B$7)*$B$8+16.0*'1. Параметры'!$B$7)*'1. Параметры'!$B$5*'1. Параметры'!$B$8/1000000 | D19: =(B19-C19)/B19 | E19: ='3. Цена сообщения'!C12 | F19: =C19*'1. Параметры'!$B$6 | G19: =B19-C19
A21: Влияние на маржу тарифа Pro (балансный mix, 200 msg/мес)
A23: Сценарий | B23: Сообщений | C23: Без кеша COGS | D23: С кешем COGS | E23: Экономия ₽/мес | F23: Маржа Pro: было → стало
A24: Lite пользователь, 200 msg бал. | B24: 200 | C24: =200*'6. Mix-сценарии'!C15 | D24: =200*(B12*'6. Mix-сценарии'!C5+B13*'6. Mix-сценарии'!C6+B14*'6. Mix-сценарии'!C7+B15*'6. Mix-сценарии'!C8+B16*'6. Mix-сценарии'!C9+B17*'6. Mix-сценарии'!C10+B18*'6. Mix-сценарии'!C11+B19*'6. Mix-сценарии'!C12) | E24: =C24-D24 | F24: =ROUND(C24/7990*100,1)&"% → "&ROUND(D24/7990*100,1)&"%"
A25: Pro средний, 600 msg бал. | B25: 600 | C25: =600*'6. Mix-сценарии'!C15 | D25: =600*(B12*'6. Mix-сценарии'!C5+B13*'6. Mix-сценарии'!C6+B14*'6. Mix-сценарии'!C7+B15*'6. Mix-сценарии'!C8+B16*'6. Mix-сценарии'!C9+B17*'6. Mix-сценарии'!C10+B18*'6. Mix-сценарии'!C11+B19*'6. Mix-сценарии'!C12) | E25: =C25-D25 | F25: =ROUND(C25/7990*100,1)&"% → "&ROUND(D25/7990*100,1)&"%"
A26: Pro power-user, 1200 msg бал. | B26: 1200 | C26: =1200*'6. Mix-сценарии'!C15 | D26: =1200*(B12*'6. Mix-сценарии'!C5+B13*'6. Mix-сценарии'!C6+B14*'6. Mix-сценарии'!C7+B15*'6. Mix-сценарии'!C8+B16*'6. Mix-сценарии'!C9+B17*'6. Mix-сценарии'!C10+B18*'6. Mix-сценарии'!C11+B19*'6. Mix-сценарии'!C12) | E26: =C26-D26 | F26: =ROUND(C26/7990*100,1)&"% → "&ROUND(D26/7990*100,1)&"%"
A27: Pro power-user премиум, 300 msg | B27: 300 | C27: =300*'6. Mix-сценарии'!D15 | D27: =300*(B12*'6. Mix-сценарии'!D5+B13*'6. Mix-сценарии'!D6+B14*'6. Mix-сценарии'!D7+B15*'6. Mix-сценарии'!D8+B16*'6. Mix-сценарии'!D9+B17*'6. Mix-сценарии'!D10+B18*'6. Mix-сценарии'!D11+B19*'6. Mix-сценарии'!D12) | E27: =C27-D27 | F27: =ROUND(C27/7990*100,1)&"% → "&ROUND(D27/7990*100,1)&"%"

Sheet 12. Qwen self-hosted
A1: Когда self-hosted Qwen 3 235B окупится
A2: Capex 250к ₽ (1×A100 80GB или 2×RTX 4090) + Opex ~120к/мес. Break-even зависит от объёма traffic.
A4: Параметр | B4: Значение | C4: Комментарий
A5: Покупка железа | B5: 250000 | C5: 1× A100 80GB ИЛИ 2× RTX 4090, 256 ГБ RAM
A6: Текущие траты в месяц (электричество, охлаждение, износ за 5 лет) | B6: 120000 | C6: Включая 4 100 кВт×час × 6 ₽/кВт + 50% капекса/60
A7: Производительность 1 видеокарты, сообщ/час | B7: 60 | C7: Реалистично для 235B на A100 при batch=4
A8: Время работы, часов/мес | B8: 720 | C8: 30 дней × 24 часа (всегда запущен)
A9: Доля задач, которые можно роутить на Qwen | B9: 0.3 | C9: Простые правки, типовые задачи. 40-50% при умном роутинге.
A11: Сколько сообщ может обработать в мес | B11: =B7*B8 | C11: на 1 GPU
A12: Себест 1 сообщ на Qwen, ₽ | B12: =B6/B11 | C12: opex / capacity
A13: Если бы платили API (DeepSeek) | B13: =B11*'3. Цена сообщения'!B5
A14: Если бы платили API (Haiku) | B14: =B11*'3. Цена сообщения'!B8
A15: Если бы платили API (Sonnet) | B15: =B11*'3. Цена сообщения'!B11
A18: Активных Pro юзеров | B18: Msg/мес всего (200/юзер) | C18: Msg на Qwen (30%) | D18: Если бы Sonnet, ₽ | E18: Себест на Qwen, ₽ | F18: Экономия /мес | G18: Месяцев до точки безубыточности
A19: 50 | B19: 10000 | C19: =B19*$B$9 | D19: =C19*'3. Цена сообщения'!B11 | E19: =$B$6 | F19: =D19-E19 | G19: =IF(F19<=0,"никогда",ROUND($B$5/F19,1))
A20: 100 | B20: 20000 | C20: =B20*$B$9 | D20: =C20*'3. Цена сообщения'!B11 | E20: =$B$6 | F20: =D20-E20 | G20: =IF(F20<=0,"никогда",ROUND($B$5/F20,1))
A21: 200 | B21: 40000 | C21: =B21*$B$9 | D21: =C21*'3. Цена сообщения'!B11 | E21: =$B$6 | F21: =D21-E21 | G21: =IF(F21<=0,"никогда",ROUND($B$5/F21,1))
A22: 500 | B22: 100000 | C22: =B22*$B$9 | D22: =C22*'3. Цена сообщения'!B11 | E22: =$B$6 | F22: =D22-E22 | G22: =IF(F22<=0,"никогда",ROUND($B$5/F22,1))
A23: 1000 | B23: 200000 | C23: =B23*$B$9 | D23: =C23*'3. Цена сообщения'!B11 | E23: =$B$6 | F23: =D23-E23 | G23: =IF(F23<=0,"никогда",ROUND($B$5/F23,1))
A24: 2000 | B24: 400000 | C24: =B24*$B$9 | D24: =C24*'3. Цена сообщения'!B11 | E24: =$B$6 | F24: =D24-E24 | G24: =IF(F24<=0,"никогда",ROUND($B$5/F24,1))
A25: 5000 | B25: 1000000 | C25: =B25*$B$9 | D25: =C25*'3. Цена сообщения'!B11 | E25: =$B$6 | F25: =D25-E25 | G25: =IF(F25<=0,"никогда",ROUND($B$5/F25,1))
A27: ВЕРДИКТ
A28: • До 100 активных Pro юзеров: Qwen НЕ окупается — opex 120к/мес больше чем экономия на API.
A29: • 200-500 юзеров: 4-12 мес до точки безубыточности. Прицельно если есть стратегические причины (152-ФЗ, vendor lock-in protection).
A30: • 500+ юзеров: 1-3 мес до точки безубыточности — однозначно ставить.
A31: • По плану на M15: ~1 000 платящих → точки безубыточности на 4-м месяце с launch'a Qwen.
A32: • Альтернатива до тех пор: остаёмся на DeepSeek + Haiku API. COGS низкий, гибкость высокая.
A34: СТРАТЕГИЧЕСКАЯ ЦЕННОСТЬ (за пределами точки безубыточности)
A35: ★ 152-ФЗ-compliant: Qwen self-hosted = ПДн остаётся в нашем периметре. Открывает enterprise-сегмент.
A36: ★ Vendor lock-in protection: если Anthropic/OpenAI ограничат доступ из РФ — мы не встаём.
A37: ★ Маркетинг: «Open-source LLM в нашем контуре» = differentiation от Promto/Lovable/v0.
A38: ★ R&D-площадка: можем fine-tune под наши задачи (code-gen для рос-стека: Tilda, ЮKassa, 1С API).

Sheet 13. Lean opex
A1: Lean cost-структура · только реальные траты
A2: Только то, что нужно: юрист + LLM (variable) + Серверум + домены/SSL + 300к/мес разработка. Никаких лишних FOT и маркетинговых бюджетов.
A4: ПОСТОЯННЫЕ ЗАТРАТЫ (₽/мес, не зависят от числа клиентов)
A6: Категория | B6: ₽/мес | C6: Комментарий
A7: Юрист | B7: 30000 | C7: Договоры, оферта, ИП/ЮЛ обслуживание, нерегулярные консультации
A9: ИТОГО ПОСТОЯННЫХ | B9: =B7
A11: ПОЧЕМУ ТАК МАЛО ПОСТОЯННЫХ?
A12: • Разработку делают founders сами — без зарплат. AI-инструменты делают это реальным даже для одного человека.
A13: • Серверум и домен клиента — в стоимости подписки (variable per customer), не наши fixed.
A14: • Маркетинг с M2 (после запуска): 100 → 250 К/мес ramp. Если clipboard окупает себя — масштабируем.
A15: • Юрист — единственная обязательная статья (договоры, оферта, документы по 152-ФЗ).
A16: ПЕРЕМЕННЫЕ ЗАТРАТЫ (₽/клиент/мес, профиль B — балансный)
A18: Тариф | B18: Цена ₽/мес | C18: LLM-COGS (wallet/markup) | D18: Серверум · сервер для сайта клиента | E18: Домен клиента + HTTPS | F18: Комиссия 3% | G18: Итого Var | H18: Gross маржа ₽ | I18: Маржа %
A19: Lite | B19: 990 | C19: =1000/'1. Параметры'!$B$6 | D19: 50 | E19: 25 | F19: =B19*0.03 | G19: =C19+D19+E19+F19 | H19: =B19-G19 | I19: =H19/B19
A20: Starter | B20: 2990 | C20: =2500/'1. Параметры'!$B$6 | D20: 600 | E20: 50 | F20: =B20*0.03 | G20: =C20+D20+E20+F20 | H20: =B20-G20 | I20: =H20/B20
A21: Pro | B21: 7990 | C21: =6000/'1. Параметры'!$B$6 | D21: 3000 | E21: 100 | F21: =B21*0.03 | G21: =C21+D21+E21+F21 | H21: =B21-G21 | I21: =H21/B21
A22: Enterprise | B22: 19990 | C22: =18000/'1. Параметры'!$B$6 | D22: 8000 | E22: 250 | F22: =B22*0.03 | G22: =C22+D22+E22+F22 | H22: =B22-G22 | I22: =H22/B22
A24: • LLM-COGS = wallet ₽ / markup 2.8 (т.к. wallet это retail-цена токенов).
A25: • Если клиент НЕ сжигает весь wallet — наш COGS меньше, маржа выше.
A26: • Серверум — passthru от SafeCloud / CORTEL по партнёрскому прайсу + наша наценка уже в подписке.
A27: • Домен клиента: .ru/.рф ~300 ₽/год от Reg.ru → 25 ₽/мес. Включается в тариф.
A28: • HTTPS-сертификат от Let's Encrypt — бесплатно, авто-обновление.

Sheet 14. Lean точки безубыточности
A1: Точка безубыточности · сколько платящих клиентов нужно
A2: Зависит от микса тарифов. Чем больше Pro/Ent в миксе, тем меньше клиентов нужно.
A4: ДОЛИ ТАРИФОВ В МИКСЕ
A6: Lite | B6: 0.5
A7: Starter | B7: 0.25
A8: Pro | B8: 0.18
A9: Enterprise | B9: 0.07
A10: Сумма (= 100%) | B10: =SUM(B6:B9)
A13: ВЗВЕШЕННЫЕ ПОКАЗАТЕЛИ
A15: Средний доход с клиента, ₽ | B15: =B6*'13. Lean opex'!B21+B7*'13. Lean opex'!B22+B8*'13. Lean opex'!B21+B9*'13. Lean opex'!B22
A16: Маржа на 1 клиента/мес, ₽ | B16: =B6*'13. Lean opex'!H21+B7*'13. Lean opex'!H22+B8*'13. Lean opex'!H21+B9*'13. Lean opex'!H22
A17: Маржа % от выручки | B17: =B16/B15
A20: ТОЧКА БЕЗУБЫТОЧНОСТИ
A22: Постоянный opex, ₽/мес | B22: ='13. Lean opex'!B9
A23: Платящих клиентов нужно | B23: =ROUNDUP(B22/B16,0)
A24: Выручка/мес для безубыточности, ₽ | B24: =B23*B15
A27: ЧУВСТВИТЕЛЬНОСТЬ ПО МИКСУ
A29: Сценарий | B29: Lite % | C29: Starter % | D29: Pro % | E29: Ent % | F29: Доход/клиент ₽ | G29: Маржа/клиент ₽ | H29: Клиентов до плюса
A30: Зрелый (M15+, default) | B30: 0.5 | C30: 0.25 | D30: 0.18 | E30: 0.07 | F30: =B30*'13. Lean opex'!B21+C30*'13. Lean opex'!B22+D30*'13. Lean opex'!B21+E30*'13. Lean opex'!B22 | G30: =B30*'13. Lean opex'!H21+C30*'13. Lean opex'!H22+D30*'13. Lean opex'!H21+E30*'13. Lean opex'!H22 | H30: =ROUNDUP('13. Lean opex'!B9/G30,0)
A31: Лит-доминантный (M5-9) | B31: 0.8 | C31: 0.15 | D31: 0.04 | E31: 0.01 | F31: =B31*'13. Lean opex'!B21+C31*'13. Lean opex'!B22+D31*'13. Lean opex'!B21+E31*'13. Lean opex'!B22 | G31: =B31*'13. Lean opex'!H21+C31*'13. Lean opex'!H22+D31*'13. Lean opex'!H21+E31*'13. Lean opex'!H22 | H31: =ROUNDUP('13. Lean opex'!B9/G31,0)
A32: Бизнес-mix (M10-14) | B32: 0.6 | C32: 0.25 | D32: 0.12 | E32: 0.03 | F32: =B32*'13. Lean opex'!B21+C32*'13. Lean opex'!B22+D32*'13. Lean opex'!B21+E32*'13. Lean opex'!B22 | G32: =B32*'13. Lean opex'!H21+C32*'13. Lean opex'!H22+D32*'13. Lean opex'!H21+E32*'13. Lean opex'!H22 | H32: =ROUNDUP('13. Lean opex'!B9/G32,0)
A33: Премиум-tilt (M18+) | B33: 0.3 | C33: 0.25 | D33: 0.3 | E33: 0.15 | F33: =B33*'13. Lean opex'!B21+C33*'13. Lean opex'!B22+D33*'13. Lean opex'!B21+E33*'13. Lean opex'!B22 | G33: =B33*'13. Lean opex'!H21+C33*'13. Lean opex'!H22+D33*'13. Lean opex'!H21+E33*'13. Lean opex'!H22 | H33: =ROUNDUP('13. Lean opex'!B9/G33,0)
A34: Только Pro/Ent (B2B fokus) | B34: 0 | C34: 0 | D34: 0.7 | E34: 0.3 | F34: =B34*'13. Lean opex'!B21+C34*'13. Lean opex'!B22+D34*'13. Lean opex'!B21+E34*'13. Lean opex'!B22 | G34: =B34*'13. Lean opex'!H21+C34*'13. Lean opex'!H22+D34*'13. Lean opex'!H21+E34*'13. Lean opex'!H22 | H34: =ROUNDUP('13. Lean opex'!B9/G34,0)
A37: ВЫВОД: при дефолтном миксе точки безубыточности ≈ 280 платящих. При премиум-tilt — всего ~145.
A38: vs v2 business plan (с маркетингом и FOT 3.5М/мес): точки безубыточности был 858 → теперь 280 = в 3× меньше.

Sheet 15. Финмодель 24 мес
A1: Финмодель 24 месяца · структура расходов как доля выручки
A2: Зарплаты = 30% выручки (с минимумом 30к в M1-M4) · Токены+инфра = 30% · Бэкофис (VPS клиенту + домены + операционка) = 10% · Маркетинг = отдельно фиксированно. Платящие пересчитаны под маркетинговую реальность 2026.
A4: Параметр | B4: M1 | C4: M2 | D4: M3 | E4: M4 | F4: M5 | G4: M6 | H4: M7 | I4: M8 | J4: M9 | K4: M10 | L4: M11 | M4: M12 | N4: M13 | O4: M14 | P4: M15 | Q4: M16 | R4: M17 | S4: M18 | T4: M19 | U4: M20 | V4: M21 | W4: M22 | X4: M23 | Y4: M24
A5: Платящие клиенты (накопленно) | B5: 0 | C5: 10 | D5: 30 | E5: 75 | F5: 165 | G5: 300 | H5: 480 | I5: 660 | J5: 870 | K5: 1100 | L5: 1380 | M5: 1670 | N5: 1980 | O5: 2330 | P5: 2710 | Q5: 3120 | R5: 3550 | S5: 4000 | T5: 4400 | U5: 4800 | V5: 5200 | W5: 5550 | X5: 5900 | Y5: 6250
A6: Средний доход с клиента, ₽/мес | B6: 0 | C6: 990 | D6: 990 | E6: 1100 | F6: 1200 | G6: 1400 | H6: 1700 | I6: 2000 | J6: 2300 | K6: 2600 | L6: 2900 | M6: 3150 | N6: 3400 | O6: 3650 | P6: 3850 | Q6: 3950 | R6: 4030 | S6: 4080 | T6: 4080 | U6: 4100 | V6: 4120 | W6: 4140 | X6: 4150 | Y6: 4160
A7: ВЫРУЧКА, ₽/мес | B7: =B5*B6 | C7: =C5*C6 | D7: =D5*D6 | E7: =E5*E6 | F7: =F5*F6 | G7: =G5*G6 | H7: =H5*H6 | I7: =I5*I6 | ... Y7: =Y5*Y6
A9: Зарплаты (30% выручки или 30к, что больше), ₽ | B9: =MAX(30000,B7*0.3) | C9: =MAX(30000,C7*0.3) | D9: =MAX(30000,D7*0.3) | E9: =MAX(30000,E7*0.3) | F9: =MAX(30000,F7*0.3) | G9: =MAX(30000,G7*0.3) | H9: =MAX(30000,H7*0.3) | I9: =MAX(30000,I7*0.3) | ... Y9: =MAX(30000,Y7*0.3)
A10: Токены + наша инфра (30% выручки), ₽ | B10: =B7*0.3 | C10: =C7*0.3 | D10: =D7*0.3 | E10: =E7*0.3 | F10: =F7*0.3 | G10: =G7*0.3 | H10: =H7*0.3 | I10: =I7*0.3 | ... Y10: =Y7*0.3
A11: Бэкофис: VPS клиентов + домены + опер (10%), ₽ | B11: =B7*0.1 | C11: =C7*0.1 | D11: =D7*0.1 | E11: =E7*0.1 | F11: =F7*0.1 | G11: =G7*0.1 | H11: =H7*0.1 | I11: =I7*0.1 | ... Y11: =Y7*0.1
A12: Маркетинг и реклама (фиксированный бюджет), ₽ | B12: 0 | C12: 100000 | D12: 100000 | E12: 100000 | F12: 100000 | G12: 150000 | H12: 150000 | I12: 150000 | J12: 150000 | K12: 200000 | L12: 200000 | M12: 200000 | N12: 200000 | O12: 200000 | P12: 250000 | Q12: 250000 | R12: 250000 | S12: 250000 | T12: 250000 | U12: 250000 | V12: 300000 | W12: 300000 | X12: 300000 | Y12: 300000
A14: ИТОГО ОПЕРАЦИОННЫХ РАСХОДОВ, ₽ | B14: =SUM(B9:B12) | C14: =SUM(C9:C12) | D14: =SUM(D9:D12) | E14: =SUM(E9:E12) | F14: =SUM(F9:F12) | G14: =SUM(G9:G12) | H14: =SUM(H9:H12) | I14: =SUM(I9:I12) | ... Y14: =SUM(Y9:Y12)
A16: ОПЕРАЦИОННАЯ ПРИБЫЛЬ/УБЫТОК, ₽ | B16: =B7-B14 | C16: =C7-C14 | D16: =D7-D14 | E16: =E7-E14 | F16: =F7-F14 | G16: =G7-G14 | H16: =H7-H14 | I16: =I7-I14 | ... Y16: =Y7-Y14
A17: Накопленные деньги на счёте (старт 30к ₽), ₽ | B17: =30000+B16 | C17: =B17+C16 | D17: =C17+D16 | E17: =D17+E16 | F17: =E17+F16 | G17: =F17+G16 | H17: =G17+H16 | I17: =H17+I16 | J17: =I17+J16 | ... Y17: =X17+Y16
A20: ИТОГИ
A21: Выручка/мес на M24, ₽ | B21: =Y7
A22: Выручка/год на M24, ₽ | B22: =Y7*12
A23: Деньги на счёте на M24, ₽ | B23: =Y17
A24: Самый большой минус по деньгам, ₽ | B24: =MIN(B17:Y17)
A25: Платящих клиентов на M24 | B25: =Y5
A26: Месяц первой прибыли | B26: M7 (с новой структурой 30/30/10/30)
A27: Месяц возврата вложений (счёт > 0) | B27: M9
A28: Маркетинг суммарно за 24 мес, ₽ | B28: =SUM(B12:Y12)
A29: Зарплаты суммарно за 24 мес, ₽ | B29: =SUM(B9:Y9)
A30: Токены+инфра суммарно за 24 мес, ₽ | B30: =SUM(B10:Y10)
A31: Бэкофис суммарно за 24 мес, ₽ | B31: =SUM(B11:Y11)
A33: Структура: 30% зарплаты / 30% токены+инфра / 10% бэкофис / 30% операц.доход (до маркетинга)
A35: Платящих клиентов на M24 | B35: 6 250 | C35: По плану | D35: —
A36: Месяц первой прибыли | B36: M7 | C36: M6 (старая модель) | D36: +1 мес позже
A37: Месяц возврата вложений | B37: M9 | C37: M8 | D37: +1 мес позже
A38: Самый большой минус | B38: ~−380 К ₽ | C38: ~−305 К | D38: −25%
A39: Накопленные деньги на M24 | B39: ~+60 М ₽ | C39: ~+67 М (старая) | D39: −7 М
A40: Почему стало хуже? | B40: Зарплаты 30% + замедл. разгон M2-M6 | C40: В старой founders=0 | D40: —
A41: Что лучше? | B41: Каждый рубль роста = +30к в команду | C41: — | D41: Запас прочности

Sheet 16. Маркетинг 2026 (clean)
A1: Семантическое ядро · 63 ЧИСТЫХ запроса · Wordstat 2026
A2: Только запросы с явным buying intent: vertical / AI-specific / pain-driven / research. Грязные (бренд+generic+freebie) исключены — экономят бюджет в 2-3× через downstream conversion.
A4: # | B4: Запрос | C4: Категория | D4: Показов/мес 2026 | E4: Цена клика ₽ 2026 | F4: Ценность 1-5
A5: 1 | B5: сайт под ключ | C5: A. Прямой intent | D5: 18000 | E5: 135 | F5: 4
A6: 2 | B6: лендинг создать | C6: A. Прямой intent | D6: 15000 | E6: 120 | F6: 4
A7: 3 | B7: сайт самостоятельно | C7: A. Прямой intent | D7: 8000 | E7: 80 | F7: 4
A8: 4 | B8: одностраничный сайт | C8: A. Прямой intent | D8: 5000 | E8: 90 | F8: 4
A9: 5 | B9: сайт без программиста | C9: A. Прямой intent | D9: 1500 | E9: 65 | F9: 5
A10: 6 | B10: нейросеть сайт | C10: B. AI ★ | D10: 4500 | E10: 85 | F10: 5
A11: 7 | B11: ai сайт | C11: B. AI ★ | D11: 2800 | E11: 90 | F11: 5
A12: 8 | B12: нейросеть создать сайт | C12: B. AI ★ | D12: 2200 | E12: 80 | F12: 5
A13: 9 | B13: сайт через chatgpt | C13: B. AI ★ | D13: 1500 | E13: 75 | F13: 4
A14: 10 | B14: искусственный интеллект сайт | C14: B. AI ★ | D14: 1400 | E14: 80 | F14: 4
A15: 11 | B15: сделать сайт нейросетью | C15: B. AI ★ | D15: 1300 | E15: 80 | F15: 5
A16: 12 | B16: ai конструктор сайтов | C16: B. AI ★ | D16: 1200 | E16: 95 | F16: 5
... A67: 63 | B67: сделать сайт самому без программиста | C67: L. Pain ★ | D67: 400 | E67: 60 | F67: 5
B69: ИТОГО · 63 ключей | D69: =SUM(D5:D68) | E69: =AVERAGE(E5:E68)
A72: ВОРОНКА 100К ₽ → ПЛАТЯЩИЕ КЛИЕНТЫ · 4 СЦЕНАРИЯ 2026
A74: Бюджет ₽/мес | B74: 100000 | D74: ← поменяй число — пересчитается всё ниже
A76: Сценарий | B76: Цена клика ₽ | C76: Кликов = визитов | D76: Цена визита ₽ | E76: Конверсия посадочной | F76: Регистраций на пробник | G76: Пробник → платящий | H76: Платящих/мес | I76: Стоимость привлечения ₽
A77: А. Cold start M2 (clean targeting) | B77: 85 | C77: =$B$74/B77 | D77: =B77 | E77: 0.04 | F77: =C77*E77 | G77: 0.06 | H77: =F77*G77 | I77: =$B$74/H77
A78: Б. Базовая оптимизация M3 | B78: 75 | C78: =$B$74/B78 | D78: =B78 | E78: 0.05 | F78: =C78*E78 | G78: 0.07 | H78: =F78*G78 | I78: =$B$74/H78
A79: В. Vertical landing pages M4 | B79: 65 | C79: =$B$74/B79 | D79: =B79 | E79: 0.06 | F79: =C79*E79 | G79: 0.08 | H79: =F79*G79 | I79: =$B$74/H79
A80: Г. Зрелая воронка M5+ | B80: 60 | C80: =$B$74/B80 | D80: =B80 | E80: 0.07 | F80: =C80*E80 | G80: 0.09 | H80: =F80*G80 | I80: =$B$74/H80
A81: Д. Идеал M6+ (LTV/CAC 2.4) | B81: 55 | C81: =$B$74/B81 | D81: =B81 | E81: 0.08 | F81: =C81*E81 | G81: 0.1 | H81: =F81*G81 | I81: =$B$74/H81
A84: ГРАФИК ПЕРВЫХ 6 МЕСЯЦЕВ НА 100К ₽/мес DIRECT
A86: Месяц | B86: Что происходит | C86: Цена клика ₽ | D86: Конв. посадочной | E86: Прб → Плт | F86: Кликов | G86: Пробников | H86: Платящих | I86: Стоимость привлечения ₽
A87: M1 | B87: M1 Soft launch (без рекламы) | C87: — | D87: — | E87: — | F87: — | G87: — | H87: 0 | I87: —
A88: M2 | B88: M2 Cold start (clean targeting) | C88: 85 | D88: 0.04 | E88: 0.06 | F88: =$B$74/C88 | G88: =F88*D88 | H88: =G88*E88 | I88: =$B$74/H88
A89: M3 | B89: M3 Первая оптимизация | C89: 75 | D89: 0.05 | E89: 0.07 | F89: =$B$74/C89 | G89: =F89*D89 | H89: =G89*E89 | I89: =$B$74/H89
A90: M4 | B90: M4 Vertical landing pages | C90: 65 | D90: 0.06 | E90: 0.08 | F90: =$B$74/C90 | G90: =F90*D90 | H90: =G90*E90 | I90: =$B$74/H90
A91: M5 | B91: M5 Retargeting + узнаваемость | C91: 60 | D91: 0.07 | E91: 0.09 | F91: =$B$74/C91 | G91: =F91*D91 | H91: =G91*E91 | I91: =$B$74/H91
A92: M6 | B92: M6 Зрелая воронка | C92: 55 | D92: 0.08 | E92: 0.1 | F92: =$B$74/C92 | G92: =F92*D92 | H92: =G92*E92 | I92: =$B$74/H92
B93: ИТОГО за 6 мес (новых платящих) | H93: =SUM(H87:H92)
A96: РАСХОЖДЕНИЕ С ФИНПЛАНОМ (лист 15)
A98: Месяц | B98: По финплану | C98: По воронке Direct 100К | D98: Дельта | E98: Что компенсирует
A99: M1 | B99: 0 | C99: 0 | D99: 0 | E99: —
A100: M2 | B100: 30 | C100: 3 | D100: −27 | E100: Multi-channel + soft-launch buzz → 8-12
A101: M3 | B101: 80 | C101: 5 | D101: −75 | E101: VC.ru/Habr статья + первые кейсы → 25-35
A102: M4 | B102: 150 | C102: 7 | D102: −143 | E102: Vertical lendings + B2B sales → 65-85
...
